Workbook

Sheet Listing
A1: Property Address | B1: =TEXTJOIN(", ", TRUE, B20:B23) -> 8075 Catherine Ave, Pasadena, MD, 21122 | C1: =TEXTJOIN(", ", TRUE, C20:C23) -> 330 Salisbury Rd, Edgewater, MD, 21037 | D1: =TEXTJOIN(", ", TRUE, D20:D23) -> 5117 Keota Terrace, College Park, MD, 20740 | E1: =TEXTJOIN(", ", TRUE, E20:E23) -> 2404 Chestnut Terrace Ct Unit #101, Odenton, MD, 21113 | F1: =TEXTJOIN(", ", TRUE, F20:F23) -> 3501 Falling Run , Laurel , MD, 20724 | G1: =TEXTJOIN(", ", TRUE, G20:G23) -> 6312 Springbrook Ln, Clinton, MD, 20735 | H1: =TEXTJOIN(", ", TRUE, H20:H23) -> 407 Frankle St, Brooklyn, MD, 21225 | I1: =TEXTJOIN(", ", TRUE, I20:I23) -> 5129 Niagara Pl, College Park , MD, 20740 | ... M1: =TEXTJOIN(", ", TRUE, M20:M23) -> 7 Waldron Ave, Pikesville , MD, 21208 | N1: =TEXTJOIN(", ", TRUE, N21:N24) -> Middle River , MD, 21220, Baltimore | O1: =TEXTJOIN(", ", TRUE, O20:O23) -> 5129 Niagara Pl, college park , MD, 20740 | P1: =TEXTJOIN(", ", TRUE, P20:P23) -> 7 Waldron Ave, Pikesville , MD, 21208 | Q1: =TEXTJOIN(", ", TRUE, Q20:Q23) -> 6919 Decatur Place , Hyattsville, MD, 20784 | R1: =TEXTJOIN(", ", TRUE, R20:R23) -> 599 Lions Gate, Odenton, MD, 21113 | S1: =TEXTJOIN(", ", TRUE, S20:S23) -> 17 Blue Sky Dr, Owings Mill, MD, 21117 | T1: =TEXTJOIN(", ", TRUE, T20:T23) -> 2 North Star Ct, Pikesville, MD, 21208 | U1: =TEXTJOIN(", ", TRUE, U20:U23) -> 3661 Cragsmoor Rd, Ellicot City, MD, 21042 | V1: =TEXTJOIN(", ", TRUE, V20:V23) -> 24624 Showbarn Circle, Damascus, MD, 20872 | ... AK1: =TEXTJOIN(", ", TRUE, AK20:AK23)
A2: Street Number (Formula) | B2: =IFERROR(LEFT(B20,FIND(" ",B20)-1),B20) -> 8075 | C2: =IFERROR(LEFT(C20,FIND(" ",C20)-1),C20) -> 330 | D2: =IFERROR(LEFT(D20,FIND(" ",D20)-1),D20) -> 5117 | E2: =IFERROR(LEFT(E20,FIND(" ",E20)-1),E20) -> 2404 | F2: =IFERROR(LEFT(F20,FIND(" ",F20)-1),F20) -> 3501 | G2: =IFERROR(LEFT(G20,FIND(" ",G20)-1),G20) -> 6312 | H2: =IFERROR(LEFT(H20,FIND(" ",H20)-1),H20) -> 407 | I2: =IFERROR(LEFT(I20,FIND(" ",I20)-1),I20) -> 5129 | ... M2: =IFERROR(LEFT(M20,FIND(" ",M20)-1),M20) -> 7 | N2: =IFERROR(LEFT(N21,FIND(" ",N21)-1),N21) -> Middle | O2: =IFERROR(LEFT(O20,FIND(" ",O20)-1),O20) -> 5129 | P2: =IFERROR(LEFT(P20,FIND(" ",P20)-1),P20) -> 7 | Q2: =IFERROR(LEFT(Q20,FIND(" ",Q20)-1),Q20) -> 6919 | R2: =IFERROR(LEFT(R20,FIND(" ",R20)-1),R20) -> 599 | S2: =IFERROR(LEFT(S20,FIND(" ",S20)-1),S20) -> 17 | T2: =IFERROR(LEFT(T20,FIND(" ",T20)-1),T20) -> 2 | U2: =IFERROR(LEFT(U20,FIND(" ",U20)-1),U20) -> 3661 | V2: =IFERROR(LEFT(V20,FIND(" ",V20)-1),V20) -> 24624 | ... AK2: =IFERROR(LEFT(AK20,FIND(" ",AK20)-1),AK20)
A3: Street Name (Formula) | B3: =MID(B20,FIND("@",SUBSTITUTE(B20," ","@",LEN(B20)-LEN(SUBSTITUTE(B20," ",""))-(3-1)))+1,LEN(B20)) -> Catherine Ave | C3: =MID(C20,FIND("@",SUBSTITUTE(C20," ","@",LEN(C20)-LEN(SUBSTITUTE(C20," ",""))-(3-1)))+1,LEN(C20)) -> Salisbury Rd | D3: =MID(D20,FIND("@",SUBSTITUTE(D20," ","@",LEN(D20)-LEN(SUBSTITUTE(D20," ",""))-(3-1)))+1,LEN(D20)) -> Keota Terrace | E3: =MID(E20,FIND("@",SUBSTITUTE(E20," ","@",LEN(E20)-LEN(SUBSTITUTE(E20," ",""))-(3-1)))+1,LEN(E20)) -> Ct Unit #101 | F3: =MID(F20,FIND("@",SUBSTITUTE(F20," ","@",LEN(F20)-LEN(SUBSTITUTE(F20," ",""))-(3-1)))+1,LEN(F20)) -> Falling Run | G3: =MID(G20,FIND("@",SUBSTITUTE(G20," ","@",LEN(G20)-LEN(SUBSTITUTE(G20," ",""))-(3-1)))+1,LEN(G20)) -> Springbrook Ln | H3: =MID(H20,FIND("@",SUBSTITUTE(H20," ","@",LEN(H20)-LEN(SUBSTITUTE(H20," ",""))-(3-1)))+1,LEN(H20)) -> Frankle St | I3: =MID(I20,FIND("@",SUBSTITUTE(I20," ","@",LEN(I20)-LEN(SUBSTITUTE(I20," ",""))-(3-1)))+1,LEN(I20)) -> Niagara Pl | ... AK3: =MID(AK20,FIND("@",SUBSTITUTE(AK20," ","@",LEN(AK20)-LEN(SUBSTITUTE(AK20," ",""))-(3-1)))+1,LEN(AK20)) -> #VALUE!
A4: Tax ID | B4: 20338822989400 | C4: 17212330322 | D4: 17212330322 | E4: 20457190103089 | F4: 17090917732 | G4: 17090917732 | I4: 17010018655 | J4: 4151502202950 | K4: 20206090051276 | L4: 4151700006441 | M4: 4030303053560 | N4: 17020163147 | O4: 20444590073911 | P4: 1402261650 | Q4: 4042100013000 | R4: 4032200014402 | S4: 161202043215 | T4: 20315690216404 | U4: 17070815365 | V4: 160203463072 | AG4: 20341813498500 | AH4: 17161802693 | AI4: 20289290048537
A5: Timestamp (Formula) | B5: 44259.765 | C5: 44224.762 | D5: 44265.624 | E5: 44260.671 | F5: 44224.757 | G5: 44272.64 | L5: 44256.636 | M5: 44278.585 | N5: {=transpose('Import fr LIF'!41:41)} -> 44273.722 | O5: {=transpose('Import fr LIF'!42:42)} -> 44274.711 | P5: {=transpose('Import fr LIF'!43:43)} -> 44278.585 | Q5: {=transpose('Import fr LIF'!44:44)} -> 44284.651 | R5: {=transpose('Import fr LIF'!45:45)} -> 44284.726 | S5: {=transpose('Import fr LIF'!46:46)} -> 44284.797 | T5: {=transpose('Import fr LIF'!47:47)} -> 44284.8 | U5: {=transpose('Import fr LIF'!48:48)} -> 44284.804 | V5: {=transpose('Import fr LIF'!49:49)} -> 44285.639 | W5: {=transpose('Import fr LIF'!50:50)} -> 44286.553 | X5: {=transpose('Import fr LIF'!51:51)} -> 44288.631 | Y5: {=transpose('Import fr LIF'!52:52)} -> 44288.813 | Z5: {=transpose('Import fr LIF'!53:53)} -> 44293.745 | AA5: {=transpose('Import fr LIF'!54:54)} -> 44298.711 | AB5: {=transpose('Import fr LIF'!55:55)} -> 44298.742 | AC5: {=transpose('Import fr LIF'!56:56)} -> 44299.388 | AD5: {=transpose('Import fr LIF'!57:57)} -> #REF! | AE5: {=transpose('Import fr LIF'!58:58)} -> 44299.73 | AF5: {=transpose('Import fr LIF'!59:59)} -> 44301.612 | AG5: {=transpose('Import fr LIF'!60:60)} -> 44302.646 | AH5: {=transpose('Import fr LIF'!61:61)} -> 44306.735 | AI5: {=transpose('Import fr LIF'!64:64)} -> 44314.707 | AJ5: {=transpose('Import fr LIF'!65:65)} -> 44326.614 | AK5: {=transpose('Import fr LIF'!66:66)}
A6: Agent Name | B6: Justin | C6: Justin | D6: Justin | E6: Justin | F6: Justin | G6: Justin | H6: Justin | I6: Justin | J6: Shaq | K6: Justin | L6: Shaq | M6: Shaq | N6: Shaq | O6: Justin | P6: Shaq | Q6: John | R6: Justin | S6: Justin | T6: Justin | U6: Justin | V6: Justin | W6: Justin | X6: Justin | Y6: Justin | Z6: Shaq | AA6: Justin | AB6: Justin | AC6: Shaq | AE6: Justin | AF6: Shaq | AG6: Justin | AH6: Justin | AI6: John | AJ6: Justin
A7: Date of Listing Appointment | B7: 44259 | C7: 44224 | D7: 44265 | E7: 44132 | F7: 44228 | G7: 44272 | H7: 44228 | I7: 44274 | J7: 44273 | K7: 44146 | L7: 44254 | M7: 44277 | N7: 44273 | O7: 44274 | P7: 44277 | Q7: 44284 | R7: 44288 | S7: 44288 | T7: 44288 | U7: 44294 | V7: 44285 | W7: 44286 | X7: 44287 | Y7: 44289 | Z7: 44293 | AA7: 44298 | AB7: 44293 | AC7: 44299 | AE7: 44301 | AF7: 44300 | AG7: 44298 | AH7: 44302 | AI7: 44314 | AJ7: 44335
A8: Seller 1 Name | B8: Gregory Jackson | C8: Cory Chambers | D8: Dennis Lamprey | E8: Kathleen L Dipeppe | F8: Maheswaran Natarajan | G8: Aimee Smith | H8: Amy Neary | I8: Mohammad Azad & Arafa Khatun | J8: Brian Valdivia | K8: Charles Gorum | L8: Brian Valdivia | M8: Jeffrey Rattell | N8: Brian Valdivia | O8: Mohammad Azad & Arafa Khatun | P8: Jeffrey Rattell | Q8: Residential Value, LLC | R8: Matthew Lake | S8: Perry Dollar | T8: Perry Dollar | U8: Joyce Gomez | V8: Dale Crum | W8: Rodell Colbert | X8: Mary J Smith | Y8: MON-CHOU FANN | Z8: James Sasser | AA8: Harris Mohammed | AB8: William Hauserman | AC8: Joby Gallo | AE8: James McNamara | AF8: Kevin Knight | AG8: Alain Chu | AH8: Cristina M Galdieri | AI8: Residential Value, LLC | AJ8: Alvester Gales
A9: Seller 1 Phone# | B9: 4102128803 | C9: 4102181104 | D9: 301-474-3476 | E9: 4438897314 | F9: 3018757291 | G9: 3019805645 | H9: 4438526091 | I9: 240-475-1039 | J9: 443-845-2273 | L9: 443-845-2273 | M9: 410-971-0702 | N9: 443-845-2273 | O9: 240-475-1039 | P9: 410-971-0702 | Q9: 301-674-0760 | R9: 3042035801 | S9: 4438015880 | T9: 4438015880 | U9: 2022151798 | W9: 4436232982 | X9: 2024656548 | Y9: 2402520781 | Z9: 443-768-4917 | AA9: 269-352-1885 | AB9: 304 268 7705 | AC9: 410-302-8762 | AE9: 4103407877 | AF9: 609-458-3611 | AG9: 2406023091 | AH9: 2408823626 | AI9: 301-674-0760
A10: Seller 1 Email | B10: firstnationsmtg9500@gmail.com | C10: cory33_1999@yahoo.com | D10: usmc1965dwlsr1@verizon.net | F10: n.maheswaran@gmail.com | G10: aimeelouisesmith@hotmail.com | H10: amymneary@gmail.com | I10: azadppy@yahoo.com | J10: bvaldivia46@gmail.com | K10: chuck@thegorums.com | L10: bvaldivia46@gmail.com | M10: jrattell@rescomsolutions.biz | N10: bvaldivia46@gmail.com | O10: azadppy@yahoo.com | P10: jrattell@rescomsolutions.biz | Q10: dsl227@aol.com | R10: mlake05@gmail.com | S10: Perry.Dollar@perrydollar.com | T10: Perry.Dollar@perrydollar.com | U10: gjoycet@hotmail.com | V10: decrum@hotmail.com | W10: rodell34@aol.com | X10: pps24wolf@gmail.com | Z10: jimbo12130@gmail.com | AA10: mailharrisnow@yahoo.com | AB10: williamhauserman@yahoo.com | AC10: gallo120@aol.com | AE10: james.mcnamara333@gmail.com | AF10: bigduke94@gmail.com | AG10: contrau@yahoo.com | AH10: tgaldieri@varsity.com | AI10: dsl227@aol.com | AJ10: alvester.gales@yahoo.com
A11: Seller 2 Name | F11: Soorriya Natarajan | G11: Steven Smith | I11: Arafa Khatun | J11: Angelo Pagonis | K11: Lisa Gorum | L11: Angelo Pagonis | N11: Angelo Pagonis | O11: Arafa Khatun | U11: Jose Gomez | V11: Francene Crum | Y11: JIANG MAN-SHIOW | AB11: Annette Hauserman | AC11: Robin Gallo | AG11: Giao Tran | AJ11: Annie Gales
A12: Seller 2 Phone# | J12: 410-960-1876 | K12: 4432533071 | L12: 410-960-1876 | N12: 410-960-1876 | AC12: 410-508-5341
A13: Seller 2 Email | F13: Soorriya_c@yahoo.com | G13: on listing agreement | J13: alphaservicesmd@gmail.com | K13: lisa@thegorums.com | L13: alphaservicesmd@gmail.com | N13: alphaservicesmd@gmail.com | AC13: rgallo1207@aol.com | AJ13: galesann@yahoo.com
A14: Exclusive Right to Sell already signed? (8 page packet) | B14: No | C14: No | D14: Yes | E14: Yes | F14: No | G14: No | H14: No | I14: No | J14: No | K14: No | L14: No | M14: No | N14: No | O14: No | P14: No | Q14: Yes | R14: No | S14: No | T14: No | U14: No | V14: No | W14: No | X14: No | Y14: No | Z14: No | AA14: No | AB14: No | AC14: No | AE14: No | AF14: No | AG14: No | AH14: No | AI14: Yes | AJ14: No
A15: Listing Price | B15: 330000 | C15: 300000 | D15: 320000 | E15: 255000 | F15: 370000 | G15: 275000 | H15: 230000 | J15: 146000 | K15: 1100000 | L15: 215000 | M15: 245000 | N15: 146000 | P15: 245000 | Q15: 405000 | R15: 315000 | S15: 260000 | T15: 260000 | X15: 580000 | Z15: 215000 | AA15: 310000 | AB15: 310000 | AC15: 285000 | AE15: 220000 | AF15: 216000 | AG15: 315000 | AH15: 320000 | AI15: 294900 | AJ15: 500000
A16: Projected MLS Active Date | B16: 44273 | C16: 44287 | D16: 44294 | E16: 44293 | F16: 44287 | G16: 44293 | H16: 44257 | I16: 44294 | J16: 44274 | K16: 44308 | L16: 44272 | M16: 44307 | N16: 44274 | O16: 44294 | P16: 44307 | Q16: 44288 | R16: 44300 | S16: 44335 | T16: 44368 | U16: 44314 | V16: 44337 | W16: 44336 | X16: 44317 | Y16: 44368 | Z16: 44321 | AA16: 44335 | AB16: 44285 | AC16: 44321 | AE16: 44365 | AF16: 44321 | AG16: 44316 | AH16: 44377 | AI16: 44316 | AJ16: 44371
A17: Projected Coming Soon Date | B17: 44265 | C17: 44277 | D17: 44286 | E17: 44284 | F17: 44277 | G17: 44286 | H17: 44249 | I17: 44289 | J17: 44274 | K17: 44287 | L17: 44260 | M17: 44286 | N17: 44274 | O17: 44289 | P17: 44286 | Q17: 44286 | R17: 44293 | S17: 44321 | T17: 44348 | U17: 44307 | V17: 44328 | W17: 44317 | X17: 44317 | Y17: 44348 | Z17: 44300 | AA17: 44293 | AB17: 44285 | AC17: 44307 | AE17: 44351 | AF17: 44307 | AG17: 44337 | AH17: 44356 | AI17: 44316 | AJ17: 44350
A18: Total Commission | B18: 6 | C18: 6 | D18: 6 | E18: 6 | F18: 5 % | G18: 6 | H18: 5 | I18: 5 | J18: 5 | K18: 4.5 | L18: 4.5 | M18: 6 | N18: 5 | O18: 5 | P18: 6 | Q18: 3.75 | R18: 5.5 | S18: 6 | T18: 6 | U18: 6 | V18: 5 | W18: 6 | X18: 4.5 | Y18: 6 | Z18: 5 | AA18: 5 + $495 | AB18: 4 + $495 | AC18: 5 | AE18: 5 | AF18: 5 | AG18: 6 +495 | AH18: 5.5 | AI18: 3.75 | AJ18: 6
A19: Listing-Side Commission | B19: 3.5 | C19: 3.5 | D19: 3.5 | E19: 3.5 | F19: 2.5 | G19: 3.5 | H19: 2.5 | I19: 2.5 | J19: 2 | K19: 2 | L19: 2.5 | M19: 3.5 | N19: 2 | O19: 2.5 | P19: 3.5 | Q19: 1.25 | R19: 3 | S19: 3.5 | T19: 3.5 | U19: 3.5 | V19: 2.5 | W19: 3.5 | X19: 2 | Y19: 3.5 | Z19: 2.5 | AA19: 2.5 | AB19: 4 | AC19: 2.5 | AE19: 2.5 | AF19: 2.5 | AG19: 3.5 | AH19: 3 | AI19: 1.25 | AJ19: 3.5
A20: Property Street Address | B20: 8075 Catherine Ave | C20: 330 Salisbury Rd | D20: 5117 Keota Terrace | E20: 2404 Chestnut Terrace Ct Unit #101 | F20: 3501 Falling Run | G20: 6312 Springbrook Ln | H20: 407 Frankle St | I20: 5129 Niagara Pl | J20: 825 Lannerton Rd | K20: 1201 John Ross Ct | L20: 666 Kittendale Cir | M20: 7 Waldron Ave | N20: 825 Lannerton Rd | O20: 5129 Niagara Pl | P20: 7 Waldron Ave | Q20: 6919 Decatur Place | R20: 599 Lions Gate | S20: 17 Blue Sky Dr | T20: 2 North Star Ct | U20: 3661 Cragsmoor Rd | V20: 24624 Showbarn Circle | W20: 1017 Brockton Court | X20: 4805 Church Rd (Map : 0046 Grid: 00C4 Parcel: 0055) | Y20: 12109 Cypress Spring Rd | Z20: 320 Margaret Ave | AA20: 6550 Frietchie Row | AB20: 802 Edmondson Ave, 21228-4457 | AC20: 1501 Saunders Way | AE20: 27 Clearwater Ct | AF20: 5959 Benton Heights Ave | AG20: 9943 valley park dr | AH20: 2254 Commissary Cir | AI20: 1700 Manning Road Glen Burnie, MD 21061 | AJ20: 20649 Anndyke Way,
A21: City | B21: Pasadena | C21: Edgewater | D21: College Park | E21: Odenton | F21: Laurel | G21: Clinton | H21: Brooklyn | I21: College Park | J21: Middle River | K21: Crownsville | L21: Middle River | M21: Pikesville | N21: Middle River | O21: college park | P21: Pikesville | Q21: Hyattsville | R21: Odenton | S21: Owings Mill | T21: Pikesville | U21: Ellicot City | V21: Damascus | W21: Glen Burnie | X21: Bowie | Y21: Clarksburg | Z21: Baltimore | AA21: Columbia, | AB21: Baltimore | AC21: Glen Burnie | AE21: Baltimore | AF21: Baltimore | AG21: Damascus | AH21: Odenton | AI21: Glen Burnie | AJ21: Germantown,
A22: State (Initials only) | B22: MD | C22: MD | D22: MD | E22: MD | F22: MD | G22: MD | H22: MD | I22: MD | J22: MD | K22: MD | L22: MD | M22: MD | N22: MD | O22: MD | P22: MD | Q22: MD | R22: MD | S22: MD | T22: MD | U22: MD | V22: MD | W22: MD | X22: MD | Y22: MD | Z22: MD | AA22: MD | AB22: MD | AC22: MD | AE22: MD | AF22: MD | AG22: MD | AH22: MD | AI22: MD | AJ22: MD
A23: Zip Code | B23: 21122 | C23: 21037 | D23: 20740 | E23: 21113 | F23: 20724 | G23: 20735 | H23: 21225 | I23: 20740 | J23: 21220 | K23: 21032 | L23: 21220 | M23: 21208 | N23: 21220 | O23: 20740 | P23: 21208 | Q23: 20784 | R23: 21113 | S23: 21117 | T23: 21208 | U23: 21042 | V23: 20872 | W23: 21060 | X23: 20720 | Y23: 20871 | Z23: 21221 | AA23: 21045-4506 | AB23: 21228-4457 | AC23: 21061 | AE23: 21220 | AF23: 21206 | AG23: 20872 | AH23: 21113 | AI23: 21061 | AJ23: 20874
A24: County | B24: Anne Arundel | C24: Anne Arundel | D24: Prince George's | E24: Anne Arundel | F24: Anne Arundel | G24: Prince George's | H24: Baltimore City | I24: Prince George's | J24: Baltimore | K24: Anne Arundel | L24: Baltimore | M24: Baltimore | N24: Baltimore | O24: Prince George's | P24: Baltimore | Q24: Prince George's | R24: Anne Arundel | S24: Baltimore | T24: Baltimore | U24: Howard | V24: Montgomery | W24: Anne Arundel | X24: Prince George's | Y24: Montgomery | Z24: Baltimore | AA24: Howard | AB24: NOT BALTIMORE CITY | AC24: Anne Arundel | AE24: Baltimore | AF24: Baltimore City | AG24: Montgomery | AH24: Anne Arundel | AI24: Anne Arundel | AJ24: Montgomery
A25: Property Subdivision | B25: Green Haven | C25: WOODLAND BEACH | D25: HOLLYWOOD | E25: Piney Orchard | F25: RUSSETT | G25: LEWIS SPRING MANOR | H25: Brooklyn | I25: SUNNYSIDE | J25: Maplecrest | K25: BELVIOR / BELVIOR FARMS | L25: CARROLLWOOD MANOR | M25: Ralston | N25: Maplecrest | O25: SUNNYSIDE | P25: Ralston | Q25: Woodlawn | R25: Lions Gate | S25: OWINGS RIDGE | T25: BEDFORD CROSSING | U25: Font Hill | V25: Damascus Hill | W25: BROOKSTONE | Y25: GREENWAY VILLAGE | Z25: Essex | AA25: VILLAGE OF OWEN BROWN | AC25: Harundale | AE25: CARROLLWOOD MANOR | AF25: CEDMONT | AG25: DAMASCUS VALLEY PARK | AH25: SEVEN OAKS | AI25: Harundale | AJ25: CHURCHILL TOWN SECTOR
A26: Property Status | B26: Vacant | C26: Tenant Occupied | D26: Owner Occupied | E26: Owner Occupied | F26: Tenant Occupied | G26: Owner Occupied | H26: Owner Occupied | I26: Tenant Occupied | J26: Vacant | K26: Owner Occupied | L26: Vacant | M26: Vacant | N26: Vacant | O26: Tenant Occupied | P26: Vacant | Q26: Vacant | R26: Tenant Occupied | S26: Tenant Occupied | T26: Tenant Occupied | U26: Owner Occupied | V26: Owner Occupied | W26: Owner Occupied | X26: Owner Occupied | Y26: Vacant | Z26: Tenant Occupied | AA26: Tenant Occupied | AB26: Tenant Occupied | AC26: Owner Occupied | AE26: Tenant Occupied | AF26: Owner Occupied | AG26: Vacant | AH26: Tenant Occupied | AI26: Vacant | AJ26: Owner Occupied
A27: If Tenant Occupied, Provide Additional on the below: | C27: tenant leaving | F27: tenant will be leaving | H27: owner is moving to North Carolina | I27: tenant to vacate 30-60 days | O27: tenant to vacate 30-60 days | R27: tenant vacating in May 31st, will be marketing during their last month | S27: tenant out july 13th | Z27: Tenants are vacating | AB27: tenant to purchase | AE27: vacating 30-45 days | AH27: tenant hoping to purchase
A28: Is Homeowner a Maryland Resident | B28: Yes | C28: Yes | D28: Yes | E28: Yes | F28: Yes | G28: Yes | H28: Yes | I28: No | J28: Yes | K28: Yes | L28: Yes | M28: Yes | N28: Yes | O28: No | P28: Yes | Q28: Yes | R28: Yes | S28: Yes | T28: Yes | U28: Yes | V28: Yes | X28: Yes | Y28: No | Z28: Yes | AA28: Yes | AB28: No | AC28: Yes | AE28: Yes | AF28: Yes | AG28: Yes | AH28: Yes | AI28: Yes | AJ28: Yes
A29: Showing Requirements? Check all that apply | B29: Schedule online | C29: Appointment Only - Client to approve all showings | D29: Schedule online | E29: Appointment Only - Client to approve all showings | F29: Schedule online | G29: 24 Hour notice, Appointment Only - Client to approve all showings | H29: Schedule online | I29: Schedule online | J29: Schedule online, Go and Show | K29: Appointment Only - Client to approve all showings | L29: Lockbox - Sentri, Schedule online | M29: Go and Show | N29: Schedule online, Go and Show | O29: Schedule online | P29: Go and Show | R29: 24 Hour notice, Lockbox - Sentri, Schedule online | S29: 24 Hour notice, Schedule online | T29: 24 Hour notice, Schedule online | U29: 24 Hour notice, Schedule online | V29: 24 Hour notice, Lockbox - Sentri | W29: 24 Hour notice, Schedule online | X29: 24 Hour notice | Y29: Schedule online | Z29: Appointment Only - Client to approve all showings | AA29: 24 Hour notice, Lockbox - Sentri | AB29: wont be listed for showings | AC29: 2 Hour notice | AE29: Lockbox - Sentri, Schedule online | AF29: Appointment Only - Client to approve all showings | AG29: Lockbox - Sentri | AH29: no showings unless tenant cant purchase | AI29: Lockbox - Combo, Schedule online | AJ29: 24 Hour notice
A30: Lockbox Type | B30: SentriLock | C30: SentriLock | D30: SentriLock | E30: gate code and sentri lock | F30: SentriLock | G30: SentriLock | H30: SentriLock | I30: SentriLock | J30: Combo | K30: SentriLock | L30: SentriLock | M30: SentriLock | N30: Combo | O30: SentriLock | P30: SentriLock | Q30: Combo | R30: SentriLock | S30: SentriLock | T30: SentriLock | U30: SentriLock | V30: SentriLock | W30: SentriLock | X30: None | Y30: SentriLock | Z30: SentriLock | AA30: SentriLock | AB30: None | AC30: SentriLock | AE30: SentriLock | AF30: SentriLock | AG30: SentriLock | AH30: None | AI30: Combo | AJ30: SentriLock
A31: Lockbox Location | B31: front door | D31: front door | G31: front door | I31: front door | J31: Front door | K31: front door | L31: Front Door | M31: Front Door | N31: Front door | O31: front door | P31: Front Door | Q31: Front Door | R31: front door | V31: front door | W31: front door | X31: na | Y31: front door | Z31: Front Door | AA31: front door | AB31: na | AC31: Front Door | AE31: front door | AF31: Front Railing | AG31: front door | AH31: na | AI31: front door | AJ31: front door
A32: Lockbox Combo (if any) | J32: 1901 | N32: 1901 | Q32: 1108 | V32: na | W32: sentri | X32: na | Y32: na | Z32: N/A | AA32: na | AB32: na | AC32: Sentri | AE32: na | AF32: NA | AG32: na | AH32: na | AI32: 1108 | AJ32: na
A33: Sign Allowed? Please provide details on location if needed (2+ business days to install) | B33: yard post | C33: yard post | D33: yard post | E33: yard post | F33: yard post | G33: yard post | H33: yard post | I33: yard post | J33: Yes | K33: LUXURY BRANDING | L33: Yes, front yard | M33: Yes | N33: Yes | O33: yard post | P33: Yes | R33: yard post | S33: yard post | T33: yard post | U33: yard post | V33: yard post | W33: yard post | X33: yard post | Y33: yard post | Z33: Yes | AA33: yard post | AB33: no | AC33: Yes | AE33: yard post | AF33: Front Yard | AH33: na | AI33: yes | AJ33: yard post
A34: Open House Date(s) | E34: 4/10-4/11 | L34: First weekend if possible | R34: April 23-24 ?
A35: Location Type | B35: Residential | C35: Residential | D35: Residential | E35: Residential | F35: Residential | G35: Residential | H35: Residential | I35: Residential | J35: Residential | K35: Residential | L35: Residential | M35: Residential | N35: Residential | O35: Residential | P35: Residential | Q35: Residential | R35: Residential | S35: Residential | T35: Residential | U35: Residential | V35: Residential | W35: Residential | X35: selling the land, does have house | Y35: Residential | Z35: Residential | AA35: Residential | AB35: Residential | AC35: Residential | AE35: Residential | AF35: Residential | AG35: Residential | AH35: Residential | AI35: Residential | AJ35: Residential
A36: Structure Type | B36: Detached | C36: Detached | D36: Detached | E36: Unit/Flat | F36: End of Row/Townhouse | G36: Detached | H36: Detached | I36: Detached | J36: End of Row/Townhouse | K36: Detached | L36: Twin/Semi-Detached | M36: Detached | N36: End of Row/Townhouse | O36: Detached | P36: Detached | Q36: Detached | R36: End of Row/Townhouse | S36: End of Row/Townhouse | T36: End of Row/Townhouse | U36: Detached | V36: Detached | W36: Detached | X36: Detached | Y36: Detached | Z36: Detached | AA36: End of Row/Townhouse | AB36: Detached | AC36: Detached | AE36: End of Row/Townhouse | AF36: Interior Row/Town House | AG36: Interior Row/Town House | AH36: Interior Row/Town House | AI36: Detached | AJ36: Detached
A37: Ownership | B37: Fee Simple | C37: Fee Simple | D37: Fee Simple | E37: Condominium | F37: Fee Simple | G37: Fee Simple | H37: Fee Simple | I37: Fee Simple | J37: Ground Rent | K37: Fee Simple | L37: Fee Simple | M37: Fee Simple | N37: Ground Rent | O37: Fee Simple | P37: Fee Simple | Q37: Fee Simple | R37: Fee Simple | S37: Fee Simple | T37: Fee Simple | U37: Fee Simple | W37: Fee Simple | X37: Fee Simple | Y37: Fee Simple | Z37: Fee Simple | AA37: Fee Simple | AB37: Fee Simple | AC37: Fee Simple | AE37: Fee Simple | AF37: Ground Rent | AH37: Fee Simple | AI37: Fee Simple | AJ37: Fee Simple
A38: If Ground Rent: list total annual payment, frequency, of payment, the name/address/phone# of the Ground Rent holder | J38: 120 / yr | N38: 120 / yr | AF38: 90/semi anually
A39: Property Specs. [Check all that apply] | AG39: HOA
A40: Front Foot Fee & Frequency (if any) | Q40: N/A
...

Sheet Inventory
A1: Status | B1: Property Address | C1: Agent | D1: Seller 1/ Email/ Phone | E1: Seller 2/ Email/ Phone | F1: Added in RV? | G1: Opportunity | H1: HOA/Condo/Coop | I1: Sewer/Septic? | J1: Front Foot Fee? | K1: Photos Scheduled? | L1: Listing Price | M1: CS | N1: Active Date | O1: Expiration | P1: MLS Number | Q1: Sign Installation Request | R1: Add disclosures in MLS | S1: Setup Showing Instructions | T1: KW Ad in Command | U1: Send MLS Sheet out | V1: Pull tax record | W1: Lockbox assigned | X1: Source | Y1: Total Comm | Z1: LAC | AA1: BAC | AB1: Flat Fee | AC1: LA Signed Date | AD1: Buyer Name | AE1: Buyer's Agent | AF1: Financing (Cash, Conv, VA, etc) | AG1: Title | AH1: Lender | AI1: Lender Required Repairs | AJ1: Sales Price | AK1: EMD Amount | AL1: EMD Held by | AM1: Seller Contribution | AN1: Ratification Date | AO1: Closing Date | AP1: Financing Commintment | AQ1: Appraisal | AR1: Inspection | AS1: Pend in MLS | AT1: Buyer Agent Into | AU1: Seller Intro | AV1: Title Inro | AW1: TItle Docs Complete | AX1: Added Dates to Calendar | AY1: Greensheet/Commission Tab | AZ1: ALTA/HUD Received? | BA1: Order sign down | BB1: Closed in MLS | BC1: Notes | BD1: Has Dotloop? | BE1: Linked?
A2: Pre-Listing | B2: 8496 Inspiration Avenue, Walkersville, MD 21793 | C2: Justin | D2: Jarred Merriam lj_merriam@yahoo.com +13014733902 | E2: Lori Merriam | F2: TRUE | G2: TRUE | K2: 8/10 or 8/11 | P2: MDFR2003888 | Q2: FALSE | R2: FALSE | S2: FALSE | T2: FALSE | U2: FALSE | V2: TRUE | Y2: 0.06 | Z2: 0.035 | AA2: 0.025 | AB2: 495 | AC2: 44415 | AZ2: FALSE | BA2: FALSE | BC2: We would like to have coming soon 8/9/21 and photos scheduled for 8/10 or 8/11. Either photo company is fine, whoever has availability. The projected active date will be 8/12. We may look to have coming soon 8/12 and active 8/19, but for now lets shoot for the earlier timeline. MLS Draft created. MLS Missing: Marketing Date, Photos, Disclosures. | BD2: Y | BE2: Y
A3: Pre-Listing | B3: 125 Blackbird Hill Ln, Laurel, MD 20724 | C3: Justin | D3: Sherry Banks Home Mobile: 404-840-4227 Home Email: sirblubeard@gmail.com | E3: N/A | F3: TRUE | G3: TRUE | I3: Septic | K3: TRUE | O3: 44581 | P3: MDAA2006222 | Q3: FALSE | R3: FALSE | S3: FALSE | T3: FALSE | U3: FALSE | V3: TRUE | Y3: 0.055 | Z3: 0.03 | AA3: 0.025 | AB3: $595? | AC3: 44413 | AZ3: FALSE | BA3: FALSE | BC3: MLS Draft created. MLS Missing: Marketing Date, Photos, HOA Fee, Pool. Need MLS Remarks. Clarification on Commission Rate. Listing Agreement and Dotloop info has different value. No Signed Disclosures yet. | BD3: Y | BE3: N | BF3: Front fee fee Photo Schedule Staging Showing HOA Fee When are we making it Active
A4: Pre-Listing | B4: 2914 Tarragon Lane, Bowie, MD 20715 | C4: Jen | D4: James Skarwecki | E4: Anne Skarwecki tagaj@juno.com 3012620989 | F4: TRUE | G4: TRUE | O4: 44770 | P4: MDPG2006860 | Q4: FALSE | R4: FALSE | S4: FALSE | T4: FALSE | U4: FALSE | V4: TRUE | AZ4: FALSE | BA4: FALSE | BC4: MLS Draft created. MLS Missing: List Price, Marketing Date, HOA?, Property Style, Construction Materials, Water Source, Hot Water, Cooling Type, Cooling Fuel, Heating Type, Heating Fuel, Bed/Bath/Half Bath floors? Pool?, Garage Info Need Showing Instructions & Lockbox Info Need MLS Remarks No Listing Intake. No Signed Documents. 3.5 total comm? 2.5% buyer? | BD4: Y | BE4: Y
A5: Pre-Listing | B5: 500 King Farm Blvd Unit #104, Rockville, MD 20850-5839 | C5: John | F5: TRUE | G5: FALSE | P5: MDMC2008058 | Q5: FALSE | R5: FALSE | S5: FALSE | T5: FALSE | U5: FALSE | V5: FALSE | AZ5: FALSE | BA5: FALSE | BC5: Showing Instructions: Lockbox - Combo, 1108 on slider on back door CANNOT BE SCHEDULED UNTIL WEDNESDAY OF NEXT WEEK MLS Draft created. MLS Missing: Marketing Date, Expiration Date, List Price, Condo Fee, Condo Frequency, Condo Fee includes, Condo Amenities, Hot Water Source, Photos, MLS Remarks, MLS Documents. Need Showing Instructions | BD5: N | BE5: N
A6: Pre-Listing | B6: 17 Blue Sky Dr Owings Mill MD 21117 | C6: Justin | D6: Perry Dollar Home Mobile: 443-801-5880 Home Email: Perry.Dollar@perrydollar.com | E6: N/A | F6: TRUE | G6: TRUE | O6: 44649 | P6: MDBC2003924 | Q6: FALSE | R6: FALSE | S6: FALSE | T6: FALSE | U6: FALSE | V6: FALSE | Y6: 0.06 | Z6: =Y6-AA6 -> 0.035 | AA6: 0.025 | AB6: 495 | AC6: 44358 | AZ6: FALSE | BA6: FALSE | BC6: Drafted. Seller Signed LA. No Signed Disclosures Not in Opportunity MLS Draft created. MLS Missing: Marketing Date, HOA Fee & Frequency, Photos, Showing Instructions, MLS remarks Seller Signed Exclusive Rights to Sell. No Signed Disclosures. Exclusive Rights to Sell - Need Agent's signature | BD6: Y | BE6: N
A7: Pre-Listing | B7: 1006 Shreve Ct Crofton | C7: Justin | D7: Paul Kenney kenneycommunications@comcast.net 301-325-4819 | E7: N/A | F7: TRUE | G7: TRUE | Q7: FALSE | R7: FALSE | S7: FALSE | T7: FALSE | U7: FALSE | V7: FALSE | Y7: 0.06 | Z7: =Y7-AA7 -> 0.035 | AA7: 0.025 | AB7: 495 | AZ7: FALSE | BA7: FALSE | BC7: Seller Signed LA. No Signed Disclosures. Direct tenant purchase
A8: Pre-Listing | B8: 1032 Middlesex | C8: Justin | F8: FALSE | G8: FALSE | Q8: FALSE | R8: FALSE | S8: FALSE | T8: FALSE | U8: FALSE | V8: FALSE | AZ8: FALSE | BA8: FALSE | BC8: Direct tenant purchase
A9: Pre-Listing | B9: 529 Grovethorn | C9: Justin | F9: FALSE | G9: FALSE | Q9: FALSE | R9: FALSE | S9: FALSE | T9: FALSE | U9: FALSE | V9: FALSE | AZ9: FALSE | BA9: FALSE | BC9: Direct tenant purchase
A10: CS | B10: 11723B Hamilton Place, White Marsh, MD 21162 | C10: Shaq | D10: Gabriel Titalangha gtguemia@hotmail.com 410-865-9696 | E10: Hilda Ikundi mamonjohon@yahoo.com 443-985-2292 | F10: TRUE | G10: TRUE | K10: TRUE | L10: 525000 | M10: 44418 | N10: 44420 | O10: 6692181 | P10: MDBC2005954 | Q10: TRUE | R10: TRUE | S10: TRUE | T10: FALSE | U10: FALSE | V10: TRUE | W10: 1897470 | Y10: 0.045 | Z10: 0.025 | AA10: 0.02 | AB10: 0 | AC10: 44410 | AZ10: FALSE | BA10: FALSE | BC10: MLS Sheet, Netsheet | BD10: Y | BE10: Y
A11: Active | B11: 3012 Rices Ln | C11: Justin | D11: Sadi Wadi Home Email: sadiwadi@hotmail.com | E11: N/A | F11: TRUE | G11: TRUE | K11: TRUE | L11: 525000 | M11: 44407 | N11: 44414 | O11: 44677 | P11: MDBC2004306 | Q11: TRUE | R11: FALSE | S11: TRUE | T11: TRUE | U11: TRUE | V11: TRUE | W11: 965407 | Y11: 0.04 | Z11: 0.015 | AA11: 0.025 | AB11: 495 | AC11: 44312 | AZ11: FALSE | BA11: FALSE | BC11: Incomplete Exclusive Rights to Sell - Need seller phone number. Need Agent's signature. Need answers on #32 Addenda. Blanks on Section #6 and #15. Need to fix the initials made on page 1, Section 3 Fee Simple/Ground Rent field. No Signed Disclosures | BD11: Y | BE11: N
A12: Active | B12: 5620 Quincy St, Hyattsville, MD 20784-1235 | C12: John | D12: David Loring Company: Residential Value Work Mobile: 301-674-0160 Work Email: dsl227@aol.com | E12: N/A | F12: TRUE | G12: TRUE | K12: TRUE | L12: 365000 | M12: 44411 | N12: 44413 | O12: 44564 | P12: MDPG2005740 | Q12: Ordered | R12: FALSE | S12: TRUE | T12: TRUE | U12: TRUE | V12: TRUE | Y12: 0.0375 | Z12: 0.0125 | AA12: 0.025 | AB12: 0 | AC12: 44411 | AZ12: FALSE | BA12: FALSE | BC12: Showing Instructions: Lockbox - Combo/Front Door/1108, Go & Show. Need to upload MLS Documents. MLS Sheet (Shared 8/5/2021) | BD12: Y | BE12: Y
A13: Active | B13: 202 Broadway Avenue, Glen Burnie, MD 21061 | C13: John | D13: David Loring Company: Residential Value Work Mobile: 301-674-0160 Work Email: dsl227@aol.com | E13: N/A | F13: TRUE | G13: TRUE | K13: TRUE | L13: 355000 | M13: 44411 | N13: 44413 | O13: 44595 | P13: MDAA2005004 | Q13: TRUE | R13: TRUE | S13: TRUE | T13: TRUE | U13: TRUE | V13: TRUE | Y13: 0.0375 | Z13: 0.0125 | AA13: 0.025 | AB13: 0 | AC13: 44411 | AZ13: FALSE | BA13: FALSE | BC13: Showing Instructions: Lockbox - Combo/Front Door/1108, Go & Show. MLS Sheet (Shared 8/5/2021) | BD13: Y | BE13: Y
A14: Active | B14: 53 Parkhill Pl, Nottingham, MD 21236 | C14: Justin | D14: Scott Reibert Home Mobile: 443-509-1526 Home Email: scottreibert1@gmail.com | E14: Linda Reibert Home Email: lindagoray@msn.com 443-722-9099 | F14: TRUE | G14: TRUE | K14: TRUE | L14: 285000 | M14: 44407 | N14: 44413 | O14: 44751 | P14: MDBC2005942 | Q14: Ordered | R14: TRUE | S14: TRUE | T14: TRUE | U14: TRUE | V14: TRUE | Y14: 0.05 | Z14: 0.025 | AA14: 0.025 | AB14: 495 | AC14: 44390 | AZ14: FALSE | BA14: FALSE | BC14: Exclusive Rights to Sell (Shared 8/5/2021) MLS Sheet (Shared 8/5/2021) | BD14: Y | BE14: Y
A15: Active | B15: 547 Dahlgreen Road, Glen Burnie, MD 21061 | C15: Romont | D15: Carla Rich 443-875-7129 newleaf64@yahoo.com | E15: N/A | F15: TRUE | G15: TRUE | K15: TRUE | L15: 234900 | M15: 44411 | N15: 44413 | O15: 44598 | P15: MDAA2005518 | Q15: None | R15: TRUE | S15: TRUE | T15: TRUE | U15: TRUE | V15: TRUE | Y15: 0.06 | Z15: =Y15-AA15 -> 0.035 | AA15: 0.025 | AB15: 495 | AC15: 44407 | AZ15: FALSE | BA15: FALSE | BC15: Need agent signatures on Notice to Buyer and Seller, LBP after 1978. Missing Listed: County Addendum | BD15: Y | BE15: N
A16: Active | B16: 802 Edmondson Ave, Baltimore 21228 | C16: Justin | D16: William Hauserman williamhauserman@yahoo.com 304 268 7705 | E16: Annette Hauserman gailh@egismail.com | F16: TRUE | G16: TRUE | K16: TRUE | L16: 339000 | M16: 44405 | N16: 44412 | O16: 44662 | P16: MDBC2004054 | Q16: TRUE | R16: FALSE | S16: TRUE | T16: TRUE | U16: TRUE | V16: TRUE | Y16: 0.055 | Z16: =Y16-AA16 -> 0.03 | AA16: 0.025 | AB16: 495 | AC16: 44301 | AZ16: FALSE | BA16: FALSE | BC16: Missing Listed: Netsheet. Need to complete KWF Communication Consent, Financial Condition, MLS Accuracy, Notice to Buyer and Seller. | BD16: Y | BE16: Y
A17: Active | B17: 4613 Cherry Valley Dr | C17: John | D17: Stuart Newman slnewman4613@gmail.com 301-404-3166 | E17: Esther Newman 301-367-4432 esther.newman1126@gmail.com | F17: TRUE | G17: TRUE | K17: TRUE | L17: 625000 | M17: N/A | N17: 44405 | O17: 44558 | P17: MDMC2008402 | Q17: TRUE | R17: TRUE | S17: TRUE | T17: TRUE | U17: TRUE | V17: TRUE | Z17: =Y17-AA17 -> 0 | AC17: 44404 | AZ17: FALSE | BA17: FALSE | BC17: Signed MLS Sheet (Shared 7/29/2021) | BD17: Y | BE17: Y
A18: Active | B18: 530 Pritchard Drive, Linthicum Heights, MD | C18: John | D18: David Loring Company: Residential Value Work Mobile: 301-674-0160 Work Email: dsl227@aol.com | E18: N/A | F18: TRUE | G18: TRUE | K18: TRUE | L18: 379900 | M18: N/A | N18: 44399 | O18: 44561 | P18: MDAA2004064 | Q18: TRUE | R18: TRUE | S18: TRUE | T18: TRUE | U18: TRUE | V18: TRUE | Z18: =Y18-AA18 -> 0 | AZ18: FALSE | BA18: FALSE | BC18: Returned Listed: Exclusive Rights to Sell - Need initials on 19.A. | BD18: Y | BE18: Y
A19: Active | B19: 22991 Westview Dr Preston, MD 21655 | C19: Romont | D19: Verna Jenkins | E19: POA Loretta McCray Home Mobile: 213-447-1244 Home Email: consultlorettamccray@gmail.com | F19: TRUE | G19: TRUE | K19: TRUE | L19: 160000 | M19: N/A | N19: 44333 | O19: 44671 | P19: MDCM125542 | Q19: TRUE | R19: TRUE | S19: TRUE | T19: TRUE | U19: TRUE | V19: TRUE | X19: SOI | Y19: 0.06 | Z19: =Y19-AA19 -> 0.06 | AB19: 495 | AC19: 44324 | AZ19: FALSE | BA19: FALSE | BC19: BAC. Link Command to Dotloop. | BD19: Y | BE19: N
A20: Off Market | B20: 1922 Baltimore Annapolis Blvd, Annapolis | C20: Justin | D20: Tricia Johnson Home Mobile: 301-919-9433 Home Email: triciajohnson5@yahoo.com Home Address: 1922 Baltimore Annapolis Annapolis, MD 21409 US | E20: N/A | F20: TRUE | G20: TRUE | K20: TRUE | L20: 725000 | M20: 44366 | N20: N/A | O20: 44730 | P20: MDAA2000720 | Q20: None | R20: TRUE | S20: TRUE | T20: TRUE | U20: TRUE | V20: TRUE | Y20: 0.06 | Z20: =Y20-AA20 -> 0.035 | AA20: 0.025 | AB20: 495 | AC20: 44365 | AZ20: FALSE | BA20: FALSE | BC20: No listing intake, MLS Draft created. documents. Agent published. Missing Listed: Notification of Dual Agency within a Team, Netsheet, Incomplete answer LBP Addendum, Signed MLS Sheet (Shared 7/13/2021), Financial Addendum needs answer. Returned Listed: Residential Property Information - Seller names and address needed on first page. Exclusive Right to Sell - Please fill in Section 6. Please fill in blanks under Section 14. Please check boxes: Consent for DA, Financial Condition, MD Property Disclosure | BD20: Y | BE20: Y
A21: Active | B21: (Farm) 3815 Back Woods Rd Westminster | C21: Justin | D21: David Brathuhn GEORGIA560@AOL.COM 4105965840 | E21: N/A | F21: TRUE | G21: TRUE | L21: 300000 | M21: N/A | N21: 44334 | O21: 44582 | P21: MDCR203222 | Q21: TRUE | Y21: 0.1 | Z21: =Y21-AA21 -> 0.075 | AA21: 0.025 | AC21: 44218 | AZ21: FALSE | BA21: FALSE | BC21: Has two entries on Command. Link Command to Dotloop. | BD21: Y | BE21: N
A22: Active | B22: (Res) 3815 Back Woods Rd Westminster | C22: Justin | D22: David Brathuhn GEORGIA560@AOL.COM 4105965840 | E22: N/A | F22: TRUE | G22: TRUE | L22: 300000 | M22: N/A | N22: 44334 | O22: 44582 | P22: MDCR202154 | Q22: TRUE | AC22: 44218 | AZ22: FALSE | BA22: FALSE | BC22: Has two entries on Command. Link Command to Dotloop. | BD22: Y | BE22: N
A23: Active | B23: 1116 & 1120 Dicus Mill Rd Millersville, MD 21108 | C23: Justin | F23: FALSE | G23: FALSE | L23: 1650000 | M23: N/A | N23: 44013 | O23: 44511 | P23: MDAA438834 | Q23: TRUE | AC23: 44737 | AZ23: FALSE | BA23: FALSE | BC23: No Opportunity. No loop | BD23: N | BE23: N
A24: Active | B24: (Farm) 1132 Dicus Mill Rd Millersville, MD 21108 | C24: Justin | F24: FALSE | G24: FALSE | L24: 2500000 | M24: N/A | N24: 44013 | O24: 44511 | P24: MDAA429230 | Q24: TRUE | AZ24: FALSE | BA24: FALSE | BC24: No loop | BD24: N | BE24: N
A25: Active | B25: (Res) 1132 Dicus Mill Rd Millersville, MD 21108 | C25: Justin | F25: FALSE | G25: FALSE | L25: 900000 | M25: N/A | N25: 44013 | O25: 44511 | P25: MDAA438826 | Q25: TRUE | AZ25: FALSE | BA25: FALSE | BC25: No loop | BD25: N | BE25: N
A26: UC | B26: 3413 Moylan Dr | C26: John | F26: TRUE | G26: TRUE | K26: TRUE | M26: N/A | N26: 44372 | O26: 44518 | P26: MDPG2000788 | Q26: None | R26: TRUE | S26: TRUE | T26: TRUE | U26: TRUE | V26: TRUE | Y26: 0.0375 | Z26: 0.0125 | AA26: 0.025 | AB26: 0 | AC26: 44368 | AD26: William Umanzor and Veronica Umanzor | AE26: Cristhian Gonzalez | AF26: Conventional | AJ26: 500000 | AK26: 5000 | AN26: 44387 | AO26: 44417 | AS26: TRUE | AT26: N/A | AX26: N/A | AY26: Drafted | AZ26: FALSE | BA26: NA | BC26: Clear to Close | BD26: Y | BE26: Y
A27: UC | B27: 212 Gloucester Dr | C27: John | F27: TRUE | G27: TRUE | K27: TRUE | M27: N/A | N27: 44365 | O27: 44549 | P27: MDAA2000718 | Q27: None | R27: TRUE | S27: TRUE | T27: TRUE | U27: TRUE | V27: TRUE | Y27: 0.0375 | Z27: 0.0125 | AA27: 0.025 | AB27: 0 | AC27: 44375 | AD27: Tomas Guevara Carcamo and Henry Maldonado Bejarano | AE27: Noel Reyes | AF27: Conventional | AJ27: 320000 | AK27: 3200 | AN27: 44377 | AO27: 44418 | AS27: TRUE | AT27: N/A | AX27: N/A | AY27: Submitted | AZ27: FALSE | BA27: NA | BC27: COE moving to 8/10/2021. Missing UC: Need signed County Addendum. Returned Listed: MD RPD Disclosure Disclaimer - Need answer on page 4, Latent Defects. KWF Smoke Alarm - Need answer on first question. Returned UC: MD RPD Disclosure Disclaimer - Need answer on page 4, Latent Defects | BD27: Y | BE27: N
A28: UC | B28: 7906 Mansion House Crossing Pasadena | C28: Justin | F28: TRUE | G28: TRUE | K28: TRUE | M28: 44354 | N28: 44364 | O28: 44623 | P28: MDAA471220 | Q28: TRUE | R28: FALSE | S28: TRUE | T28: TRUE | U28: TRUE | V28: TRUE | Y28: 0.06 | Z28: =Y28-AA28 -> 0.035 | AA28: 0.025 | AB28: 495 | AC28: 44271 | AD28: Wei Qi Ang Gao | AE28: Han Wen Liu | AF28: Conventional | AJ28: 295000 | AK28: 5000 | AN28: 44370 | AO28: 44418 | AS28: TRUE | AT28: N/A | AX28: N/A | AY28: Drafted | AZ28: FALSE | BA28: TRUE | BC28: Clear to Close | BD28: Y | BE28: Y
A29: UC | B29: 1201 John Ross Ct | C29: Justin | F29: TRUE | G29: TRUE | K29: TRUE | M29: 44346 | N29: 44364 | O29: 44627 | P29: MDAA462562 | Q29: TRUE | R29: FALSE | S29: TRUE | T29: TRUE | U29: TRUE | V29: TRUE | Y29: 0.045 | Z29: =Y29-AA29 -> 0.02 | AA29: 0.025 | AB29: 495 | AC29: 44276 | AD29: David Hargadon and Kathryn Hargadon | AE29: Jeannie Miller | AF29: Conventional | AJ29: 1000000 | AK29: 9800 | AN29: 44372 | AO29: 44418 | AS29: TRUE | AT29: N/A | AX29: N/A | AY29: Drafted | AZ29: FALSE | BA29: TRUE | BC29: Missing Listed: Netsheet (Shared). Returned UC: Notice to Buyer and Seller - Need Buyer Agent's signature. | BD29: Y | BE29: Y
A30: UC | B30: 11 Old Station Rd Severna Park MD 21146 | C30: Patrick | D30: Patrick Codd Company: Keller Williams Flagship of Maryland Work Mobile: 443.534.3855 Work Email: pcodd@kw.com | E30: N/A | F30: TRUE | G30: TRUE | K30: TRUE | M30: 44357 | N30: 44358 | O30: 44440 | P30: MDAA471260 | Q30: TRUE | R30: TRUE | S30: TRUE | T30: TRUE | U30: TRUE | V30: TRUE | X30: Owner | AA30: 0.025 | AC30: 44349 | AD30: Michael Cornecelli and Ellie Cornecelli | AE30: Mark Hudson | AF30: Conventional | AJ30: 525000 | AK30: 15000 | AN30: 44368 | AO30: 44425 | AS30: TRUE | AT30: N/A | AX30: FALSE | AY30: Drafted | AZ30: FALSE | BA30: FALSE | BC30: Missing Listed: Netsheet | BD30: Y | BE30: Y
A31: UC | B31: 2254 Commissary Cir Odenton | C31: Justin | F31: TRUE | G31: TRUE | K31: TRUE | N31: 44385 | O31: 44671 | P31: MDAA2000894 | Q31: TRUE | R31: FALSE | S31: TRUE | T31: TRUE | U31: TRUE | V31: TRUE | Y31: 0.055 | Z31: =Y31-AA31 -> 0.03 | AA31: 0.025 | AB31: 495 | AC31: 44312 | AD31: Joseph Fong | AE31: Abhay Chaudhari | AF31: Conventional | AJ31: 361500 | AK31: 4000 | AN31: 44391 | AO31: 44425 | AS31: TRUE | AT31: N/A | AX31: TRUE | AZ31: FALSE | BA31: FALSE | BC31: Returned Listed: Exclusive Right to Sell - Initials needed on Fee Simple/Ground Rent Missing UC: EMD, HOA Docs Price Change Addendum on loop. Waiting for signatures. | BD31: Y | BE31: Y
A32: UC | B32: 560 Maryland Ave Lusby, MD 20657 | C32: Vince | D32: Mike Ricker Home Mobile: 301-536-7407 Home Email: mikericker560@yahoo.com | E32: N/A | F32: TRUE | G32: TRUE | K32: TRUE | M32: 44342 | N32: 44349 | O32: 44561 | P32: MDCA183196 | Q32: TRUE | R32: TRUE | S32: TRUE | T32: TRUE | U32: TRUE | V32: TRUE | X32: SOI | Y32: 0.05 | Z32: 0.025 | AA32: 0.025 | AB32: 495 | AC32: 44336 | AD32: Earnest Hairston and Michele Reese | AE32: Megan Ferra | AF32: FHA | AJ32: 335000 | AK32: 2500 | AN32: 44394 | AO32: 44425 | AS32: TRUE | AT32: N/A | AX32: FALSE | AZ32: FALSE | BA32: FALSE | BC32: Missing UC: Buyer signed County Addendum | BD32: Y | BE32: Y
A33: UC | B33: 8206 Courtland Manor Rd | C33: Evan | F33: TRUE | G33: TRUE | K33: TRUE | M33: 44404 | N33: 44405 | O33: 44469 | P33: MDBC2003180 | Q33: TRUE | R33: TRUE | S33: TRUE | T33: TRUE | U33: TRUE | V33: TRUE | Y33: 0.045 | Z33: 0.025 | AA33: 0.02 | AB33: 0 | AC33: 44377 | AD33: Ameta Coleman | AE33: Jennifer Kramer dela Cruz | AF33: FHA | AJ33: 221500 | AK33: 3000 | AN33: 44406 | AO33: 44428 | AS33: TRUE | AT33: N/A | AX33: FALSE | AZ33: FALSE | BA33: FALSE | BC33: Need to Split Contract Documents | BD33: Y | BE33: Y
A34: UC | B34: 7 Waldron Ave Pikesville | C34: Shaq | F34: TRUE | G34: TRUE | K34: FALSE | M34: 44378 | N34: 44379 | O34: 44643 | P34: MDBC523312 | Q34: TRUE | R34: FALSE | S34: TRUE | T34: TRUE | U34: TRUE | V34: TRUE | Y34: 0.05 | Z34: =Y34-AA34 -> 0.025 | AA34: 0.025 | AB34: 495 | AC34: 44369 | AD34: Kuba Sinla Ogundare and Beauty T Jenty Benjamin | AE34: Uchenna Onyewu | AF34: FHA | AJ34: 265000 | AK34: 5000 | AN34: 44392 | AO34: 44434 | AS34: TRUE | AT34: N/A | AX34: FALSE | AZ34: FALSE | BA34: FALSE | BC34: Returned UC: FHA Addendum - Interest rate needed. Missing Listed: Signed Netsheet (Shared 7/23/2021) | BD34: Y | BE34: N
A35: UC | B35: 8008 Dalesford Road, Parkville, MD 21234 | C35: Jen | F35: TRUE | G35: TRUE | K35: TRUE | M35: 44355 | N35: 44357 | O35: 44439 | P35: MDBC532202 | Q35: TRUE | R35: FALSE | S35: TRUE | T35: TRUE | U35: TRUE | V35: TRUE | Y35: 0.05 | Z35: 0.025 | AA35: 0.025 | AB35: 495 | AC35: 44350 | AD35: Gemcraft Homes Inc. | AE35: Lisa Hiatt | AF35: Cash | AJ35: 110000 | AK35: 5000 | AN35: 44383 | AO35: 44435 | AS35: TRUE | AT35: N/A | AX35: FALSE | AZ35: FALSE | BA35: FALSE | BC35: Clear to close. | BD35: Y | BE35: Y
A36: UC | B36: 637 Gayle Dr Linthicum Heights, MD 21090 | C36: Justin | F36: TRUE | G36: TRUE | K36: TRUE | M36: 44361 | N36: 44385 | O36: 44701 | P36: MDAA471822 | Q36: TRUE | R36: FALSE | S36: TRUE | T36: TRUE | U36: TRUE | V36: TRUE | Y36: 0.05 | Z36: 0.025 | AA36: 0.025 | AB36: 495 | AC36: 44336 | AD36: Padre S Gilliam | AE36: Harold Peters | AF36: VA | AJ36: 426500 | AK36: 1000 | AN36: 44390 | AO36: 44435 | AS36: TRUE | AT36: N/A | AX36: FALSE | AZ36: FALSE | BA36: FALSE | BC36: Missing Listed: Netsheet (Out for signature), Signed MLS Sheet (Shared 7/13/2021) Returned Listed: Exclusive Right to Sell - Seller phone number/email needed. Fill in Section 3 blanks and initials on Fee Simple/Ground Rent. | BD36: Y | BE36: Y
A37: UC | B37: 3220 Pine Crest Ct | C37: Shaq | F37: TRUE | G37: TRUE | K37: TRUE | N37: 44390 | O37: 44561 | P37: MDHR2001202 | Q37: TRUE | R37: FALSE | S37: TRUE | T37: TRUE | U37: TRUE | V37: TRUE | Y37: 0.05 | Z37: 0.025 | AA37: 0.025 | AB37: 495 | AC37: 44389 | AD37: Ahmed Jaloudi and Eman Alnatsheh | AE37: Angela Daniller | AF37: FHA | AJ37: 260000 | AK37: 1000 | AN37: 44392 | AO37: 44435 | AS37: TRUE | AT37: N/A | AX37: TRUE | AZ37: FALSE | BA37: FALSE | BC37: Missing Listed: Netsheet (Shared 7/23/2021) Missing UC: Proof of Funds | BD37: Y | BE37: Y
A38: UC | B38: 1354 Hazel Nut Ct | C38: Justin | F38: TRUE | G38: TRUE | K38: TRUE | M38: 44393 | N38: 44399 | O38: 44736 | P38: MDAA2003690 | Q38: TRUE | R38: TRUE | S38: TRUE | T38: TRUE | U38: TRUE | V38: TRUE | Y38: 0.06 | Z38: 0.035 | AA38: 0.025 | AB38: 495 | AC38: 44372 | AD38: Michael E. Lougee & Betty R. Lougee | AE38: Beth Costello | AF38: Conventional | AJ38: 251000 | AK38: 10000 | AN38: 44406 | AO38: 44435 | AS38: TRUE | AT38: N/A | AX38: FALSE | AZ38: FALSE | BA38: FALSE | BC38: Missing Listed: Netsheet, signed MD Residential Property Information, Signed MLS Sheet (Shared 7/22/2021) Missing Agent's signature and initials on Disclosure Info LBP, Competitive Market Analysis, LBP after 1978, Notice to Buyer and Seller, Exclusive Right to Sell | BD38: Y | BE38: Y
A39: UC | B39: 789 Old Herald Harbor Rd, Crownsville, MD 21032 | C39: Vince | F39: TRUE | G39: TRUE | K39: TRUE | M39: 44392 | N39: 44399 | O39: 44561 | P39: MDAA2003632 | Q39: TRUE | R39: TRUE | S39: TRUE | T39: TRUE | U39: TRUE | V39: TRUE | Y39: 0.05 | Z39: 0.025 | AA39: 0.025 | AB39: 495 | AC39: 44378 | AD39: Evan Pickett & Christine Picciot | AE39: Katerina Erhard | AF39: Conventional | AJ39: 475000 | AK39: 10000 | AN39: 44407 | AO39: 44435 | AS39: TRUE | AT39: N/A | AX39: FALSE | AZ39: FALSE | BA39: FALSE | BC39: MLS Sheet (Shared 8/2/2021) UC: Copy of EMD, Fix County Addendum 2 Opportunities in command? | BD39: Y | BE39: Y
A40: UC | B40: 307 Dogwood Rd Millersville | C40: Justin | F40: TRUE | G40: TRUE | K40: TRUE | M40: 44396 | N40: 44406 | O40: 44621 | P40: MDAA2003634 | Q40: TRUE | R40: FALSE | S40: TRUE | T40: TRUE | U40: TRUE | V40: TRUE | Y40: 0.06 | Z40: =Y40-AA40 -> 0.035 | AA40: 0.025 | AB40: 495 | AC40: 44265 | AD40: Gerald G Stansbury & Neva G Stansbury | AE40: Ray Sharif | AF40: VA | AJ40: 460000 | AK40: 5000 | AN40: 44411 | AO40: 44438 | AS40: TRUE | AT40: N/A | AW40: Out to sellers | AX40: FALSE | AZ40: FALSE | BA40: FALSE | BC40: Need MLS Remarks. Need uploaded signed disclosures on MLS. Returned Listed: Exclusive Right to Sell - Need initials on fee simple/ground rent. Need Agent Signature. KWF Competitive Market - Need Agent Signature. Notice to Buyer and Seller - Need to complete seller signatures and need agent signature.. Disclosure Info LBP - Need Agent initials and signature. Smoke Alarm Disclosure - Need answers. Waiting on the signatures for Financial Condition and MD Residential Property Information. Need to split documents. Incomplete Contract: Need to complete informations Listing and Buying Agent. | BD40: Y | BE40: Y
...

Sheet Sheet64
A1: Property | B1: Status | C1: Agent | D1: Active | E1: Photos | F1: HOA Ordered | G1: UC | H1: COE | I1: HI Schedule | J1: HI Contingency | K1: PIN | L1: EMD Received | M1: Repairs Status | N1: Appraisal | O1: Closing Scheduled | P1: Clear to close | Q1: Prelim ALTA | R1: Compliance | S1: Notes
A2: 3730 Greenmount Ave | B2: Purchase | C2: Shaq
A3: 8330 Pulaski Hwy Unit H | B3: Leased | S3: Tentatively we will put it to Flagship first end of February and coming soon end of March.
A4: 9524 Clocktower Lane | B4: Purchase | C4: Evan
A5: 1105 W 40th St | B5: Under Contract | C5: Jen | D5: 44568 | E5: 44566.438 | F5: N/A | I5: 44573.583 | R5: Listed - Submitted 01/06/2022 | S5: Dryer - Exclusion
A6: 502 Hamlen Rd | B6: Under Contract | C6: John | D6: 44897 | E6: 12/1 10:30 (TRU) | F6: N/A | G6: 44536 | H6: 44573 | I6: 44542.438 | J6: 44543 | K6: Completed | L6: 44545 | N6: Completed | O6: Completed | P6: 44199 | Q6: 44201 | R6: Listed Approve - 01/06/2022 -- -- -- -- -- UC Returned - 01/06/22 * Notice to Buyer and Seller - Buyer Name needed in Page 1 | S6: Clear to close Need repair receipts: The furnace flue vent is rusted and deteriorated down to the roof level of the home. Repair/replace as necessary to restore the integrity of the metal chimney as intended. - Pending Replace/repair the soft wood-rotten wood on the left side rear of the home. - Completed Provide documentation for permits requested through the county for the recently completed property renovations. Repair the gas supply line to the furnace so the section of the fuel line running through the chassis of the furnace is appropriately protected against contact damage. - Completed Repair/replace the missing or fallen insulation in the crawl space and make repairs as necessary to restore the insulation between the floor joists. - Completed Remove the excess construction debris and other materials from the crawl space. - Completed
A7: 737 Concord Point | B7: Purchase | C7: Shaq | D7: N/A | E7: N/A | F7: N/A | G7: 44514 | H7: 44575 | I7: N/A | J7: N/A | K7: N/A | L7: Completed | M7: N/A | N7: N/A | R7: Approved
A8: 404 Carl Avenue | B8: Purchase | C8: Paul | D8: N/A | E8: N/A | F8: N/A | G8: 44554 | H8: 44210 | I8: AS IS W/O | J8: As is w/o Inspections | K8: N/A | L8: Completed | M8: N/A | N8: N/A | P8: N/A | R8: Approved
A9: 733 Stinchcomb Road | B9: Purchase | C9: Paul | D9: N/A | E9: N/A | F9: N/A | G9: 44559 | H9: 44220 | I9: N/A | J9: N/A | K9: N/A | L9: Completed | M9: N/A | N9: N/A | P9: N/A | R9: UC - Notice to Buyer and Seller - not in dotloop
A10: 6 Colonial Dr | B10: Under Contract | C10: John | D10: 44528 | E10: 44526 | F10: N/A | G10: 44558 | H10: 44224 | I10: 12/30/2021 12:30 PM 1/4/2022 10AM WDI | J10: 44200 | K10: DONE 1/1/2021 - PIN 1/6/2021 - Seller | L10: 44564 | N10: At Value | R10: Approved | S10: * MD Lead Prevention needing signature * 1/1 - PIN received Pg.2 "Safety Concerns"- have a licensed HVAC professional remedy the possible gas leak located on the furnace. - Completed Pg. 2 "Safety Concerns"- Have a licensed electrician install a proper drip loop on the service entrance cable - To be done week of 1/3
A11: 302 Bethune Dr | B11: Under Contract | C11: Vince | D11: 44480 | E11: N/A | F11: Completed | G11: 44487 | H11: 44587 | I11: N/A | J11: N/A | K11: N/A | L11: 44491 | M11: N/A | N11: N/A | R11: Approved
A12: 301 Bethune Dr | B12: Under Contract | C12: Vince | D12: 44480 | E12: N/A | F12: Completed | G12: 44546 | H12: 44224 | I12: N/A | J12: N/A | K12: N/A | L12: 44567 | M12: N/A | N12: N/A | R12: Listed Approved - 12/30/2021 UC Approved - 12/30/2021
A13: 4654 Mews Dr | B13: Under Contract | C13: Justin | D13: 44553 | E13: 44552 | F13: 44558 | G13: 44558 | H13: 44224 | I13: 44559.667 | J13: 1/4/2021 As is | L13: 44566 | R13: Listed Resubmitted - 01/07/2022 * Net Proceeds - Uploaded * Financial Condition of Property Disclosure - Select 1 option (same since returned) * Smoke Alarm Disclosure and MAR Infographic - requires option (same since returned) -- -- -- -- -- UC Approved - 01/06/2022
A14: 304 Bethune Dr | B14: Under Contract | C14: Vince | D14: 44480 | E14: N/A | F14: Completed | G14: 44544 | H14: 1/31/2022 or Sooner | I14: N/A | J14: N/A | K14: N/A | L14: 44544 | M14: N/A | N14: N/A | R14: Listed Approved - 12/30/2021 -- -- -- -- -- UC Resubmitted - 01/07/2022 * Conventional Addendum
A15: 305 Bethune Dr | B15: Under Contract | C15: Vince | D15: 44480 | E15: N/A | F15: Completed | G15: 44523 | H15: No Guaranteed Closing | I15: N/A | J15: N/A | K15: N/A | L15: 44554 | M15: N/A | N15: N/A | R15: Approved | S15: · Addendum correcting Kathy to Kathleen. · Provide the occupancy cert when the home is complete.
A16: 303 Bethune Dr | B16: Under Contract | C16: Vince | D16: 44480 | E16: N/A | F16: Completed | G16: 44537 | H16: No Guaranteed Closing | I16: N/A | J16: N/A | K16: N/A | L16: 44543 | M16: N/A | N16: N/A | R16: Approved
A17: 319 Top Cottage Ct | B17: Purchase | C17: Shaq | D17: N/A | E17: N/A | F17: N/A | G17: 44536 | H17: No Guaranteed Closing | I17: N/A | J17: N/A | K17: N/A | L17: 44536 | M17: N/A | R17: UC Returned - 12/16/2021 * Exclusive Buyer/Tenant Representation Agreement - Missing * KWF- Communication Consent Addendum - Missing * KWF- RESPA
A18: 263 S Robinson Street | B18: Purchase | C18: Evan | D18: N/A | E18: N/A | F18: N/A | G18: 44553 | H18: 44228 | I18: TBD | J18: TBD | K18: TBD | L18: 44560 | M18: TBD | R18: Approved
A19: 7507 Overlook Ct | B19: Under Contract | C19: John | D19: 44560 | E19: 44561.5 | G19: 44568 | H19: 44603 | I19: 44574.5 | R19: UC - EMD | S19: OFFER - $549,000 VA, No Concession, AS IS w/ 7 days INSP (Regina Pierce) 1/5/22
A20: 19801 Grave Run Road | B20: Under Contract | C20: Vince | D20: 44448 | E20: N/A | F20: N/A | G20: 44566 | H20: 44631 | R20: Listed - Approved
A21: 1410 N Forest Park Ave | B21: CS | C21: Justin | E21: 44568.521 | R21: Listed Submitted - 01/07/2022
A22: 513 Beebe Ct | B22: Active | C22: John | D22: 44558 | E22: 12/29/2021 11AM | R22: Listed Submitted - 12/30/2021 | S22: OFFER - $285k FHA 1/1/22
A23: 11808 Huggins Dr | B23: Active | C23: John | D23: 44536 | E23: 44535 | F23: N/A | R23: Listed Returned - Exclusive Right To Sell - Seller initials requires in Sec 10, 18, 19 and 21. * Financial Condition of Property Disclosure - Need to select option * MLS Full Listing SIGNED by seller - MLS Listing needed. Wrong docs uploaded
A24: 9531 Burton Ave | B24: Active | C24: Jen | D24: 44534 | E24: 44532.615 | F24: N/A | R24: UC - Resubmitted 01/05/2022
A25: 800 Slacum St | B25: Active | C25: Romont | D25: 44523 | E25: 44520.542 | F25: N/A | R25: Listed - Approved 11/29/2021
A26: 3012 Rices Ln | B26: Active | C26: Justin | D26: 44414 | E26: N/A | F26: N/A | R26: UC Approved - 09/28/2021
A27: 1116 & 1120 Dicus Mill Rd | B27: Active | C27: Justin | D27: 44013 | E27: N/A | F27: N/A
A28: (Farm) 1132 Dicus Mill Rd | B28: Active | C28: Justin | D28: 44013 | E28: N/A | F28: N/A
A29: (Res) 1132 Dicus Mill Rd | B29: Active | C29: Justin | D29: 44013 | E29: N/A | F29: N/A
A30: 5659 Selford Rd | B30: Upcoming | C30: Shaq | S30: 12/26: Seller have covid19
A31: 8028 Maywood Ave | B31: Upcoming | C31: Vince
A32: 2129 Sunnythorn Rd | B32: Upcoming | C32: Jen
A33: 2128 Fountain Hill Dr | B33: Upcoming | C33: Vince
A34: 108 S 3rd St | B34: Upcoming | C34: Romont
A35: 4805 Frazier Neck Rd | B35: Upcoming | C35: Romont
A36: 3033 Lundt Ct | B36: Upcoming | C36: Justin
A37: 990 Dalton Ave | B37: Upcoming | C37: Shaq
A38: 3900 Chesterwood Dr | B38: Upcoming | C38: Vince
A39: 15907 Perkins Ln | B39: Upcoming | C39: John
A40: 3533 Falling Run Rd | B40: Upcoming | C40: Shaq | S40: Some point they will sell this year
...

Sheet Sheet65
A1: Property | B1: 2922 Sylvan | C1: 4654 Mews Dr | D1: 9524 Clocktower Lane | E1: 301 Bethune Dr | F1: 303 Bethune Dr | G1: 304 Bethune Dr | H1: 302 Bethune Dr | I1: 305 Bethune Dr | J1: 19801 Grave Run Road | K1: 719 Hamlen Rd Glen Burnie | L1: 1105 W 40Th St Baltimore, MD 21211 | M1: 7507 Overlook Ct | N1: 6 Disney Ave | O1: 2810 Belair Dr | P1: 2129 Sunnythorn Rd | Q1: 513 Beebe Ct | R1: 1410 N Forest Park Ave | S1: 7844 Citadel Dr | T1: 319 Top Cottage Ct | U1: 3730 Greenmount Ave | V1: * | W1: 108 S 3rd St | X1: 3900 Chesterwood Dr | Y1: 505 Arbor Court, Edgewood, MD 21040 | Z1: 505 Wheatley | AA1: 504 Wheatley | AB1: 503 Wheatley | AC1: 502 Wheatley | AD1: 501 Wheatley | AE1: 301 Cheddington Rd | AF1: 11808 Huggins Dr | AG1: 9531 Burton Ave | AH1: 800 Slacum St | AI1: 3012 Rices Ln | AJ1: * | AK1: 321 Magothy Blvd | AL1: 2801 Deepwater Trl | AM1: 12912 Churchill Ridge Cir Unit 5-B, Germantown, MD 20874 | AN1: 440 Century Vista Dr | AO1: 3219 Elliott St, Baltimore, MD 21224 | AP1: 26 Steeplejack Ct. Owings Mills, MD 21117 | AQ1: 5821 Farmview AVe | AR1: 1320 Highland Drive | AS1: 15415 Reprise Terr Rockville | AT1: 814 Glacier Ave | AU1: 11715 Kingtree St | AV1: 1910 Everglade Ct, Crofton, MD 21114 | AW1: 5005 Leroy Graham Dr, Capitol Heights, MD 20743 | AX1: 5659 Selford Rd | AY1: 8028 Maywood Ave | AZ1: 2128 Fountain Hill Dr | BA1: 4805 Frazier Neck Rd | BB1: 3033 Lundt Ct | BC1: 15907 Perkins Ln | BD1: 3533 Falling Run Rd | BE1: 2914 Tarragon Lane | BF1: 1006 Shreve Ct | BG1: 1032 Middlesex Rd | BH1: 529 Grovethorn Rd | BI1: * | BJ1: 263 S Robinson Street | BK1: 737 Concord Point Dr, Perryville, MD 21903 | BL1: 6 Colonial Dr | BM1: 7134 Gough St | BN1: 733 Stinchcomb Road | BO1: 404 Carl Avenue | BP1: 502 Hamlen Rd | BQ1: 8330 Pulaski Hwy Unit H | BR1: 327 George Ave | BS1: 2104 Goodwood Rd | BT1: 990 Dalton Ave | BU1: (Farm) 1132 Dicus Mill Rd | BV1: 1116 & 1120 Dicus Mill Rd | BW1: (Res) 1132 Dicus Mill Rd
A2: Status | B2: Purchase | C2: Under Contract | D2: Purchase | E2: Under Contract | F2: Under Contract | G2: Under Contract | H2: Under Contract | I2: Under Contract | J2: Under Contract | K2: Under Contract | L2: Under Contract | M2: Under Contract | N2: Under Contract | O2: Under Contract | P2: Under Contract | Q2: Under Contract | R2: Under Contract | S2: Under Contract | T2: Purchase | U2: Purchase | V2: * | W2: Coming Soon | X2: Coming Soon | Y2: Coming Soon | Z2: Coming Soon | AA2: Coming Soon | AB2: Coming Soon | AC2: Coming Soon | AD2: Coming Soon | AE2: Active | AF2: Active | AG2: Active | AH2: Active | AI2: Active | AJ2: * | AK2: Signed LA | AL2: Signed LA | AM2: Signed LA | AN2: Signed LA | AO2: Signed LA | AP2: Upcoming | AQ2: Upcoming | AR2: Lease | AS2: Upcoming | AT2: Upcoming | AU2: Upcoming | AV2: Upcoming | AW2: Upcoming | AX2: Upcoming | AY2: Upcoming | AZ2: Upcoming | BA2: Upcoming | BB2: Upcoming | BC2: Upcoming | BD2: Upcoming | BE2: Upcoming | BF2: Upcoming | BG2: Upcoming | BH2: Upcoming | BI2: * | BJ2: Closed | BK2: Closed | BL2: Closed | BM2: Closed | BN2: Closed | BO2: Closed | BP2: Closed | BQ2: Closed | BR2: Closed | BS2: Closed | BT2: Withdrawn | BU2: Withdrawn | BV2: Withdrawn | BW2: Withdrawn | BX2: AS of January 31, 2022
A3: Agent | B3: Shaq | C3: Justin | D3: Evan | E3: Vince | F3: Vince | G3: Vince | H3: Vince | I3: Vince | J3: Vince | K3: John | L3: Jen | M3: John | N3: Vince | O3: John | P3: Jen | Q3: John | R3: Justin | S3: John | T3: Shaq | U3: Shaq | V3: * | W3: Romont | X3: Vince | Y3: Shaq | Z3: Vince | AA3: Vince | AB3: Vince | AC3: Vince | AD3: Vince | AE3: John | AF3: John | AG3: Jen | AH3: Romont | AI3: Justin | AJ3: * | AK3: Cole | AL3: Justin | AM3: Justin | AN3: John | AO3: Jen | AP3: Brandt | AQ3: Jen | AR3: Jen | AS3: John | AT3: John | AU3: John | AV3: Shenel | AW3: Shaq | AX3: Shaq | AY3: Vince | AZ3: Vince | BA3: Romont | BB3: Justin | BC3: John | BD3: Shaq | BE3: Jen | BF3: Justin | BG3: Justin | BH3: Justin | BI3: * | BJ3: Evan | BK3: Shaq | BL3: John | BM3: Shaq | BN3: Paul | BO3: Paul | BP3: John | BQ3: Shaq | BR3: Evan | BS3: John | BT3: Shaq | BU3: Justin | BV3: Justin | BW3: Justin | BX3: Closed | BY3: 10
A4: Active Date | C4: 44553 | D4: N/A | E4: 44480 | F4: 44480 | G4: 44480 | H4: 44480 | I4: 44480 | J4: 44448 | K4: 44575 | L4: 44568 | M4: 44560 | N4: 44589 | O4: 44581 | Q4: 44558 | R4: 44576 | S4: 44585 | T4: N/A | U4: N/A | V4: * | W4: 44595 | X4: 44601 | Y4: 44595 | Z4: 44591 | AA4: 44591 | AB4: 44591 | AC4: 44591 | AD4: 44591 | AE4: 44589 | AF4: 44536 | AG4: 44534 | AH4: 44534 | AI4: 44414 | AJ4: * | AN4: 44595 | BI4: * | BJ4: N/A | BK4: N/A | BL4: 44528 | BM4: N/A | BN4: N/A | BO4: N/A | BP4: 44897 | BQ4: NA | BR4: Off Market Sale | BS4: 44511 | BU4: 44013 | BV4: 44013 | BW4: 44013 | BX4: Target | BY4: 300
